Workbook
Name 缺陷: '缺陷 3xx'!$B$2:$D$52
Name 天賦: '天賦 3xx'!$B$2:$D$28

Sheet 空白卡
B2: 角色名稱 | Y2: 生命狀況 | AJ2: 角色狀態 | AT2: 意志力 | BS2: =SUM(BS5:BT26) -> 0 | BU2: 缺陷 | CO2: =(IF($BS$2<0 , $BS$2*(-1),$BS$2) /2)-SUM($CO$5:$CP$14) -> 0 | CQ2: 天賦
Y3: 生命值 | AE3: 生命狀態 | AJ3: =_xlfn.IFS( AB13>=AB5,"死亡", AB9+AB11+AB13-AB5>0,"需要轉化傷勢", AB7+AB9+AB11+AB13>0,"存活" ) -> 存活 | AT3: 總上限 | AX3: =BM40 -> 4 | BB3: 已消耗 | BF3: 0 | BJ3: 意志力加值 | BN3: =3+X24*2+if((BP54&""="TRUE"),BZ54,0) -> 3 | BS3: 缺陷 等級 | BU3: 缺陷名稱 | CA3: 缺陷效果 | CO3: 天賦 等級 | CQ3: 天賦名稱 | CW3: 天賦效果
B4: 玩家名稱 | I4: 性別
Y5: 總生命 | AB5: =BM37 -> 7 | AJ5: 能量池/刻度 | AZ5: 不良狀態/其他效果 | BU5: 畸形（-1） | CA5: =VLOOKUP(BU5,'缺陷 3xx'!B:D,3,FALSE) -> 描述：無論是由於邪惡的魔法、疾病或神明的懲罰，你身上有一處先天的畸形，嚴重影響你的身體活動。 你的敏捷相關檢定承受2DP減值。 | CQ5: - | CW5: =VLOOKUP(CQ5,'天賦 3xx'!B:D,3,FALSE) -> -
B6: 身高 | G6: 體重 | K6: 年齡 | AJ6: 名稱 | AO6: 已消耗/累積 | AR6: 上限 | AU6: 備註 | AZ6: 狀態 | BD6: 關鍵抵抗屬性 | BL6: 點數 | BU6: 備註 | CQ6: 備註
B7: cm | G7: kg | Y7: 完好 | AB7: =AB5-AB9-AB11-AB13 -> 7 | BN7: ="/"&max(vlookup(BD7,$C$18:$Z$26,20,false),vlookup(BH7,$C$18:$Z$26,20,false))*(max(vlookup(BD7,$C$18:$Z$26,22,false),vlookup(BH7,$C$18:$Z$26,22,false))+1)&"/"&sum(vlookup(BD7,$C$18:$Z$26,20,false),vlookup(BH7,$C$18:$Z$26,20,false))*(sum(vlookup(BD7,$C$18:$Z$26,22,false),vlookup(BH7,$C$18:$Z$26,22,false))+1) -> #N/A | BU7: - | CA7: =VLOOKUP(BU7,'缺陷 3xx'!B:D,3,FALSE) -> - | CQ7: - | CW7: =VLOOKUP(CQ7,'天賦 3xx'!B:D,3,FALSE) -> -
B8: 外貌/特徵 | BN8: ="/"&max(vlookup(BD8,$C$18:$Z$26,20,false),vlookup(BH8,$C$18:$Z$26,20,false))*(max(vlookup(BD8,$C$18:$Z$26,22,false),vlookup(BH8,$C$18:$Z$26,22,false))+1)&"/"&sum(vlookup(BD8,$C$18:$Z$26,20,false),vlookup(BH8,$C$18:$Z$26,20,false))*(sum(vlookup(BD8,$C$18:$Z$26,22,false),vlookup(BH8,$C$18:$Z$26,22,false))+1) -> #N/A | BU8: 備註 | CQ8: 備註
Y9: 衝擊 | AB9: 0 | BN9: ="/"&max(vlookup(BD9,$C$18:$Z$26,20,false),vlookup(BH9,$C$18:$Z$26,20,false))*(max(vlookup(BD9,$C$18:$Z$26,22,false),vlookup(BH9,$C$18:$Z$26,22,false))+1)&"/"&sum(vlookup(BD9,$C$18:$Z$26,20,false),vlookup(BH9,$C$18:$Z$26,20,false))*(sum(vlookup(BD9,$C$18:$Z$26,22,false),vlookup(BH9,$C$18:$Z$26,22,false))+1) -> #N/A | BU9: - | CA9: =VLOOKUP(BU9,'缺陷 3xx'!B:D,3,FALSE) -> - | CQ9: - | CW9: =VLOOKUP(CQ9,'天賦 3xx'!B:D,3,FALSE) -> -
BN10: ="/"&max(vlookup(BD10,$C$18:$Z$26,20,false),vlookup(BH10,$C$18:$Z$26,20,false))*(max(vlookup(BD10,$C$18:$Z$26,22,false),vlookup(BH10,$C$18:$Z$26,22,false))+1)&"/"&sum(vlookup(BD10,$C$18:$Z$26,20,false),vlookup(BH10,$C$18:$Z$26,20,false))*(sum(vlookup(BD10,$C$18:$Z$26,22,false),vlookup(BH10,$C$18:$Z$26,22,false))+1) -> #N/A | BU10: 備註 | CQ10: 備註
B11: 性格/個性 | Y11: 嚴重 | AB11: 0 | BN11: ="/"&max(vlookup(BD11,$C$18:$Z$26,20,false),vlookup(BH11,$C$18:$Z$26,20,false))*(max(vlookup(BD11,$C$18:$Z$26,22,false),vlookup(BH11,$C$18:$Z$26,22,false))+1)&"/"&sum(vlookup(BD11,$C$18:$Z$26,20,false),vlookup(BH11,$C$18:$Z$26,20,false))*(sum(vlookup(BD11,$C$18:$Z$26,22,false),vlookup(BH11,$C$18:$Z$26,22,false))+1) -> #N/A | BU11: - | CA11: =VLOOKUP(BU11,'缺陷 3xx'!B:D,3,FALSE) -> - | CQ11: - | CW11: =VLOOKUP(CQ11,'天賦 3xx'!B:D,3,FALSE) -> -
BN12: ="/"&max(vlookup(BD12,$C$18:$Z$26,20,false),vlookup(BH12,$C$18:$Z$26,20,false))*(max(vlookup(BD12,$C$18:$Z$26,22,false),vlookup(BH12,$C$18:$Z$26,22,false))+1)&"/"&sum(vlookup(BD12,$C$18:$Z$26,20,false),vlookup(BH12,$C$18:$Z$26,20,false))*(sum(vlookup(BD12,$C$18:$Z$26,22,false),vlookup(BH12,$C$18:$Z$26,22,false))+1) -> #N/A | BU12: 備註 | CQ12: 備註
Y13: 惡性 | AB13: 0 | BN13: ="/"&max(vlookup(BD13,$C$18:$Z$26,20,false),vlookup(BH13,$C$18:$Z$26,20,false))*(max(vlookup(BD13,$C$18:$Z$26,22,false),vlookup(BH13,$C$18:$Z$26,22,false))+1)&"/"&sum(vlookup(BD13,$C$18:$Z$26,20,false),vlookup(BH13,$C$18:$Z$26,20,false))*(sum(vlookup(BD13,$C$18:$Z$26,22,false),vlookup(BH13,$C$18:$Z$26,22,false))+1) -> #N/A | BU13: - | CA13: =VLOOKUP(BU13,'缺陷 3xx'!B:D,3,FALSE) -> - | CQ13: - | CW13: =VLOOKUP(CQ13,'天賦 3xx'!B:D,3,FALSE) -> -
BN14: ="/"&max(vlookup(BD14,$C$18:$Z$26,20,false),vlookup(BH14,$C$18:$Z$26,20,false))*(max(vlookup(BD14,$C$18:$Z$26,22,false),vlookup(BH14,$C$18:$Z$26,22,false))+1)&"/"&sum(vlookup(BD14,$C$18:$Z$26,20,false),vlookup(BH14,$C$18:$Z$26,20,false))*(sum(vlookup(BD14,$C$18:$Z$26,22,false),vlookup(BH14,$C$18:$Z$26,22,false))+1) -> #N/A | BU14: 備註 | CQ14: 備註
B15: =IFERROR( _xlfn.IFS(SUM($F$18:$G$26)=18,"請在建卡欄位分配您的屬性(3+2+1/6)，單屬性上限為5，總和為30。", SUMIF($F$18:$G$26,">5")>0,"創角點數上限為5，請檢查。", SUM($F$18:$G$26)+COUNTIF($F$18:$G$26,">4")=30,"創卡屬性分配完成。"),"請在建卡欄位分配您的屬性(3+2+1/6)，單屬性上限為5，總和為30。剩餘點數："&(30-SUM($F$18:$F$26)-COUNTIF($F$18:$F$26,">4"))) -> 請在建卡欄位分配您的屬性(3+2+1/6)，單屬性上限為5，總和為30。 | BU15: - | CA15: =VLOOKUP(BU15,'缺陷 3xx'!B:D,3,FALSE) -> - | CO15: 怪癖
B16: 屬性 | F16: 基礎屬性 | J16: 屬性加值 | X16: 附加成功 | AH16: 專長 | BU16: 備註 | CO16: 怪癖名稱 | CU16: 怪癖描述
F17: 建卡 | H17: 購買 | J17: 內在 | L17: 修行 | N17: 增強 | P17: 器械 | R17: 其他 | T17: 臨時 | V17: 總和 | X17: 傳屬 | AA17: 額外 | AD17: 總和 | AH17: 專長名稱 | AO17: 等級 | AQ17: 專長名稱 | AX17: 等級 | AZ17: 專長名稱 | BG17: 等級 | BI17: 專長名稱 | BP17: 等級 | BU17: - | CA17: =VLOOKUP(BU17,'缺陷 3xx'!B:D,3,FALSE) -> -
B18: 生理 | C18: 力量 | F18: 2 | V18: =SUM(F18:U18) -> 2 | X18: =QUOTIENT((V18-1),5) -> 0 | AD18: =SUM(X18:AB18) -> 0 | BU18: 備註
C19: 敏捷 | F19: 2 | V19: =SUM(F19:U19) -> 2 | X19: =QUOTIENT((V19-1),5) -> 0 | AD19: =SUM(X19:AB19) -> 0 | BU19: - | CA19: =VLOOKUP(BU19,'缺陷 3xx'!B:D,3,FALSE) -> -
C20: 耐力 | F20: 2 | V20: =SUM(F20:U20) -> 2 | X20: =QUOTIENT((V20-1),5) -> 0 | AD20: =SUM(X20:AB20) -> 0 | BU20: 備註
B21: 心智 | C21: 智力 | F21: 2 | V21: =SUM(F21:U21) -> 2 | X21: =QUOTIENT((V21-1),5) -> 0 | AD21: =SUM(X21:AB21) -> 0 | BU21: - | CA21: =VLOOKUP(BU21,'缺陷 3xx'!B:D,3,FALSE) -> -
C22: 感知 | F22: 2 | V22: =SUM(F22:U22) -> 2 | X22: =QUOTIENT((V22-1),5) -> 0 | AD22: =SUM(X22:AB22) -> 0 | BU22: 備註
C23: 決心 | F23: 2 | V23: =SUM(F23:U23) -> 2 | X23: =QUOTIENT((V23-1),5) -> 0 | AD23: =SUM(X23:AB23) -> 0 | BU23: - | CA23: =VLOOKUP(BU23,'缺陷 3xx'!B:D,3,FALSE) -> -
B24: 社交 | C24: 風度 | F24: 2 | V24: =SUM(F24:U24) -> 2 | X24: =QUOTIENT((V24-1),5) -> 0 | AD24: =SUM(X24:AB24) -> 0 | BU24: 備註
C25: 操控 | F25: 2 | V25: =SUM(F25:U25) -> 2 | X25: =QUOTIENT((V25-1),5) -> 0 | AD25: =SUM(X25:AB25) -> 0 | BU25: - | CA25: =VLOOKUP(BU25,'缺陷 3xx'!B:D,3,FALSE) -> -
C26: 沉著 | F26: 2 | V26: =SUM(F26:U26) -> 2 | X26: =QUOTIENT((V26-1),5) -> 0 | AD26: =SUM(X26:AB26) -> 0 | BU26: 備註
B27: =IFERROR( _xlfn.IFS(SUM(G30:H55)=0,"請在建卡欄位分配您的技能(6+5+4/5)，單技能上限為5，總和為20。", SUMIF(G30:H55,">5")>0,"創角技能上限為5，請檢查。", SUM(G30:H55)+countif(G30:G55,">3")+countif(G30:G55,">4")=20,"創卡技能分配完成。"),"請在建卡欄位分配您的技能(6+5+4/5)，單技能上限為5，總和為20。剩餘點數："&(20-SUM(G30:H55)-countif(G30:G55,">3")-countif(G30:G55,">4"))) -> 請在建卡欄位分配您的技能(6+5+4/5)，單技能上限為5，總和為20。 | AO27: =(1+2+3)+5+(1+2)+1 -> 15
B28: 技能 | G28: 基本等級 | Q28: 附加成功 | U28: 專業/子項 | AE28: 檢定類 | BI28: 衍生屬性 | CJ28: 人物概述
G29: 建卡 | I29: 購買 | K29: 其他來源 | O29: 總和 | Q29: 其他 | S29: 總和 | AE29: 檢定項目 | AU29: 屬性 | AX29: DP加值 | BA29: 有專業 | BD29: 無專業 | BG29: 附加 | BI29: 項目 | BM29: 數值 | BP29: 基礎 | BS29: 傳屬 | BV29: 加值
B30: 生 理 | C30: 運動 | G30: 0 | O30: =SUM(G30:N30) -> 0 | S30: =LOOKUP(O30,{0,1,5,7,9,11,13,15},{-1,0,1,2,3,4,5,6})+Q30 -> -1 | AE30: 生 理 系 | AF30: 運動 | AI30: 游泳 | AM30: 攀爬 | AQ30: 跳躍 | AU30: 力量 | BA30: =vlookup(AU30,$CZ$155:$DI$186,3,false)+vlookup(AF30,$CZ$155:$DI$186,3,false)+AX30+vlookup(AF30,$CZ$155:$DI$186,9,false)+1 -> 3 | BD30: =vlookup(AU30,$CZ$155:$DI$186,3,false)+vlookup(AF30,$CZ$155:$DI$186,3,false)+AX30+vlookup(AF30,$CZ$155:$DI$186,9,false) -> 2 | BG30: =vlookup(AU30,$CZ$155:$DI$186,5,false)+vlookup(AF30,$CZ$155:$DI$186,5,false) -> -1 | BV30: 專長 | BX30: 內在 | BZ30: 修行 | CB30: 器械 | CD30: 增強 | CF30: 其他 | CH30: 臨時
C31: 肉搏 | G31: 0 | O31: =SUM(G31:N31) -> 0 | S31: =LOOKUP(O31,{0,1,5,7,9,11,13,15},{-1,0,1,2,3,4,5,6})+Q31 -> -1 | AI31: 平衡感 | AO31: 逃脫 | AU31: 敏捷 | BA31: =vlookup(AU31,$CZ$155:$DI$186,3,false)+vlookup(AF30,$CZ$155:$DI$186,3,false)+AX31+vlookup(AF30,$CZ$155:$DI$186,9,false)+1 -> 3 | BD31: =vlookup(AU31,$CZ$155:$DI$186,3,false)+vlookup(AF30,$CZ$155:$DI$186,3,false)+AX31+vlookup(AF30,$CZ$155:$DI$186,9,false) -> 2 | BG31: =vlookup(AU31,$CZ$155:$DI$186,5,false)+vlookup(AF30,$CZ$155:$DI$186,5,false) -> -1 | BI31: 體積 | BM31: =SUM(BP31:CI31) -> 5 | BP31: 5
C32: 駕駛 | G32: 0 | O32: =SUM(G32:N32) -> 0 | S32: =LOOKUP(O32,{0,1,5,7,9,11,13,15},{-1,0,1,2,3,4,5,6})+Q32 -> -1 | AF32: 竊盜 | AI32: 竊盜 | AU32: 敏捷 | BA32: =vlookup(AU32,$CZ$155:$DI$186,3,false)+vlookup(AF32,$CZ$155:$DI$186,3,false)+AX32+vlookup(AF32,$CZ$155:$DI$186,9,false)+1 -> 3 | BD32: =vlookup(AU32,$CZ$155:$DI$186,3,false)+vlookup(AF32,$CZ$155:$DI$186,3,false)+AX32+vlookup(AF32,$CZ$155:$DI$186,9,false) -> 2 | BG32: =vlookup(AU32,$CZ$155:$DI$186,5,false)+vlookup(AF32,$CZ$155:$DI$186,5,false) -> -1 | BI32: 體型 | BM32: 中型
C33: 槍械 | G33: 0 | O33: =SUM(G33:N33) -> 0 | S33: =LOOKUP(O33,{0,1,5,7,9,11,13,15},{-1,0,1,2,3,4,5,6})+Q33 -> -1 | AI33: 隱藏物品 | AM33: 開鎖 | AQ33: 綑綁 | AU33: 智力 | BA33: =vlookup(AU33,$CZ$155:$DI$186,3,false)+vlookup(AF32,$CZ$155:$DI$186,3,false)+AX33+vlookup(AF32,$CZ$155:$DI$186,9,false)+1 -> 3 | BD33: =vlookup(AU33,$CZ$155:$DI$186,3,false)+vlookup(AF32,$CZ$155:$DI$186,3,false)+AX33+vlookup(AF32,$CZ$155:$DI$186,9,false) -> 2 | BG33: =vlookup(AU33,$CZ$155:$DI$186,5,false)+vlookup(AF32,$CZ$155:$DI$186,5,false) -> -1 | BI33: 基礎速度 | BM33: =SUM(BP33:CI33)&"米" -> 9米 | BP33: {=V18+V19+INDEX({8,16,0,5,12,1,2,5},MATCH(BM32,{"超大型","超巨型","超微型","大型","巨型","微型","小型","中型"},0))} -> 9
C34: 竊盜 | G34: 0 | O34: =SUM(G34:N34) -> 0 | S34: =LOOKUP(O34,{0,1,5,7,9,11,13,15},{-1,0,1,2,3,4,5,6})+Q34 -> -1 | AF34: 隱藏 | AI34: 躲藏 | AU34: 敏捷 | BA34: =vlookup(AU34,$CZ$155:$DI$186,3,false)+vlookup(AF34,$CZ$155:$DI$186,3,false)+AX34+vlookup(AF34,$CZ$155:$DI$186,9,false)+1 -> 3 | BD34: =vlookup(AU34,$CZ$155:$DI$186,3,false)+vlookup(AF34,$CZ$155:$DI$186,3,false)+AX34+vlookup(AF34,$CZ$155:$DI$186,9,false) -> 2 | BG34: =vlookup(AU34,$CZ$155:$DI$186,5,false)+vlookup(AF34,$CZ$155:$DI$186,5,false) -> -1 | BI34: 旅行速度 | BM34: =BP34+SUM(BV34:CI34)&"米" -> 9米 | BP34: =left(BM33,2*len(BM33)-LENB(BM33)) -> 9
C35: 隱藏 | G35: 0 | O35: =SUM(G35:N35) -> 0 | S35: =LOOKUP(O35,{0,1,5,7,9,11,13,15},{-1,0,1,2,3,4,5,6})+Q35 -> -1 | AF35: 求生 | AI35: 自然環境生存 | AO35: 追蹤 | AU35: 感知 | BA35: =vlookup(AU35,$CZ$155:$DI$186,3,false)+vlookup(AF35,$CZ$155:$DI$186,3,false)+AX35+vlookup(AF35,$CZ$155:$DI$186,9,false)+1 -> 3 | BD35: =vlookup(AU35,$CZ$155:$DI$186,3,false)+vlookup(AF35,$CZ$155:$DI$186,3,false)+AX35+vlookup(AF35,$CZ$155:$DI$186,9,false) -> 2 | BG35: =vlookup(AU35,$CZ$155:$DI$186,5,false)+vlookup(AF35,$CZ$155:$DI$186,5,false) -> -1 | BI35: 先攻 | BM35: =SUM(BP35:CI35) -> 4 | BP35: =V19+V26 -> 4 | BS35: =X26*3 -> 0
C36: 求生 | G36: 0 | O36: =SUM(G36:N36) -> 0 | S36: =LOOKUP(O36,{0,1,5,7,9,11,13,15},{-1,0,1,2,3,4,5,6})+Q36 -> -1 | AE36: 心 智 系 | AF36: 學識 | AI36: 文件解讀 | AM36: 怪物辨識 | AQ36: 知識 | AU36: 智力 | BA36: =iferror(vlookup(AU36,$CZ$155:$DI$186,3,false)+vlookup(AF36,$CZ$155:$DI$186,3,false)+AX36+vlookup(AF36,$CZ$155:$DI$186,9,false)+1,"無效") -> 無效 | BD36: =iferror(vlookup(AU36,$CZ$155:$DI$186,3,false)+vlookup(AF36,$CZ$155:$DI$186,3,false)+AX36+vlookup(AF36,$CZ$155:$DI$186,9,false),"無效") -> 無效 | BG36: =iferror(VLOOKUP(AU36,$CZ$155:$DI$186,5,false)+vlookup(AF36,$CZ$155:$DI$186,5,false),"X") -> X | BI36: 基礎防禦 | BM36: =SUM(BP36:CI36) -> 2 | BP36: =Min(V22) -> 2 | BS36: =X19+X22 -> 0
C37: 白刃 | G37: 0 | O37: =SUM(G37:N37) -> 0 | S37: =LOOKUP(O37,{0,1,5,7,9,11,13,15},{-1,0,1,2,3,4,5,6})+Q37 -> -1 | AF37: 電腦 | AI37: 駭客入侵 | AO37: 防火牆 | AU37: 智力 | BA37: =iferror(vlookup(AU37,$CZ$155:$DI$186,3,false)+vlookup(AF37,$CZ$155:$DI$186,3,false)+AX37+vlookup(AF37,$CZ$155:$DI$186,9,false)+1,"無效") -> 無效 | BD37: =iferror(vlookup(AU37,$CZ$155:$DI$186,3,false)+vlookup(AF37,$CZ$155:$DI$186,3,false)+AX37+vlookup(AF37,$CZ$155:$DI$186,9,false),"無效") -> 無效 | BG37: =iferror(VLOOKUP(AU37,$CZ$155:$DI$186,5,false)+vlookup(AF37,$CZ$155:$DI$186,5,false),"X") -> X | BI37: 生命值 | BM37: =SUM(BP37:CI37) -> 7 | BP37: {=V20+INDEX({17,37,0,10,26,1,2,5},MATCH(BM32,{"超大型","超巨型","超微型","大型","巨型","微型","小型","中型"},0))} -> 7 | BS37: =(X20*X20+X20)/2 -> 0
B38: 心 智 | C38: 學識 | G38: 0 | O38: =if(sum(G38:N38)<=0,"無效",Sum(G38:N38)) -> 無效 | S38: =if(O38="無效","X",(LOOKUP(O38,{1,5,7,9,11,13,15},{0,1,2,3,4,5,6})+Q38)) -> X | AI38: 打遊戲 | AO38: 使用電腦 | AU38: 智力 | BA38: =iferror(vlookup(AU38,$CZ$155:$DI$186,3,false)+vlookup(AF37,$CZ$155:$DI$186,3,false)+AX38+vlookup(AF37,$CZ$155:$DI$186,9,false)+1,"無效") -> 無效 | BD38: =iferror(vlookup(AU38,$CZ$155:$DI$186,3,false)+vlookup(AF37,$CZ$155:$DI$186,3,false)+AX38+vlookup(AF37,$CZ$155:$DI$186,9,false),"無效") -> 無效 | BG38: =iferror(VLOOKUP(AU38,$CZ$155:$DI$186,5,false)+vlookup(AF37,$CZ$155:$DI$186,5,false),"X") -> X | BI38: 觸及範圍 | BM38: =sum(BP38:CI38)&"米" -> 2米 | BP38: {=INDEX({4,8,0,2,6,0,2,2},MATCH(BM32,{"超大型","超巨型","超微型","大型","巨型","微型","小型","中型"},0))} -> 2
C39: 電腦 | G39: 0 | O39: =if(sum(G39:N39)<=0,"無效",Sum(G39:N39)) -> 無效 | S39: =if(O39="無效","X",(LOOKUP(O39,{1,5,7,9,11,13,15},{0,1,2,3,4,5,6})+Q39)) -> X | AF39: 調查 | AI39: 搜索 | AU39: 智力 | BA39: =iferror(vlookup(AU39,$CZ$155:$DI$186,3,false)+vlookup(AF39,$CZ$155:$DI$186,3,false)+vlookup(AF39,$CZ$155:$DI$186,9,false)+AX39+1,"無效") -> 無效 | BD39: =iferror(vlookup(AU39,$CZ$155:$DI$186,3,false)+vlookup(AF39,$CZ$155:$DI$186,3,false)+AX39+vlookup(AF39,$CZ$155:$DI$186,9,false),"無效") -> 無效 | BG39: =iferror(VLOOKUP(AU39,$CZ$155:$DI$186,5,false)+vlookup(AF39,$CZ$155:$DI$186,5,false),"X") -> X | BI39: 敏感範圍 | BM39: =sum(BP39:CI39)&"米" -> 20米 | BP39: =V22*10 -> 20 | BS39: =20*X22 -> 0
C40: 手藝類 | G40: 0 | O40: =if(sum(G40:N40)<=0,"無效",Sum(G40:N40)) -> 無效 | S40: =if(O40="無效","X",(LOOKUP(O40,{1,5,7,9,11,13,15},{0,1,2,3,4,5,6})+Q40)) -> X | AI40: 聆聽 | AM40: 偵查 | AQ40: 讀唇 | AU40: 感知 | BA40: =iferror(vlookup(AU40,$CZ$155:$DI$186,3,false)+vlookup(AF39,$CZ$155:$DI$186,3,false)+AX40+vlookup(AF39,$CZ$155:$DI$186,9,false)+1,"無效") -> 無效 | BD40: =iferror(vlookup(AU40,$CZ$155:$DI$186,3,false)+vlookup(AF39,$CZ$155:$DI$186,3,false)+AX40+vlookup(AF39,$CZ$155:$DI$186,9,false),"無效") -> 無效 | BG40: =iferror(VLOOKUP(AU40,$CZ$155:$DI$186,5,false)+vlookup(AF39,$CZ$155:$DI$186,5,false),"X") -> X | BI40: 意志力池 | BM40: =SUM(BP40:CI40) -> 4 | BP40: =V23+V26 -> 4 | BS40: =X23*3+X26*3 -> 0
G41: 0 | O41: =if(sum(G41:N41)<=0,"無效",Sum(G41:N41)) -> 無效 | S41: =if(O41="無效","X",(LOOKUP(O41,{1,5,7,9,11,13,15},{0,1,2,3,4,5,6})+Q41)) -> X | AF41: 醫學 | AI41: 急救 | AU41: 敏捷 | BA41: =iferror(vlookup(AU41,$CZ$155:$DI$186,3,false)+vlookup(AF41,$CZ$155:$DI$186,3,false)+AX41+vlookup(AF41,$CZ$155:$DI$186,9,false)+1,"無效") -> 無效 | BD41: =iferror(vlookup(AU41,$CZ$155:$DI$186,3,false)+vlookup(AF41,$CZ$155:$DI$186,3,false)+AX41+vlookup(AF41,$CZ$155:$DI$186,9,false),"無效") -> 無效 | BG41: =iferror(VLOOKUP(AU41,$CZ$155:$DI$186,5,false)+vlookup(AF41,$CZ$155:$DI$186,5,false),"X") -> X | BI41: 項目 | BM41: 檢定值 | BP41: 基礎 | BR41: 附加成功 | BV41: 加值
...

Sheet 缺陷 3xx
A1: 編號 | B1: 缺陷 | C1: 前提 | D1: 效果
A2: 0 | B2: - | C2: - | D2: -
B3: 生理類缺陷： | D3: -
A4: 1 | B4: 陂腳（-1） | C4: - | D4: 描述：你的腿腳有些問題，也許曾經受過傷。 你的基礎移動速度降低3米。 特殊：輪回之境可以修復本缺陷，這需要花費你200分。
A5: 2 | B5: 獨臂（-1） | C5: - | D5: 描述：你的肢體因為某些原因沒有了，可能是在事故中失去了。 你只有一隻胳膊和手。 特殊：你可以選擇該缺陷2次，這樣會使你失去兩條手臂。 特殊：輪回之境可以修復本缺陷，這需要花費你每條手臂200分。
A6: 3 | B6: 疤痕（-1） | C6: - | D6: 描述：你因受傷落下了顯眼且猙獰的疤痕，使你更難以隱藏你的真正容貌，還令大部分人僅僅因為你的外表就不信任你。 你在表達、交涉相關檢定分別承受2DP減值，同時你的易容檢定承受4DP減值。
A7: 4 | B7: 奴隸印記（-2） | C7: - | D7: 描述：你青春的一部分或全部都是在被奴役中度過的，這段歲月為了留下了一個烙印或紋身，時時刻刻提醒著你每次做錯事情時都會受到嚴厲處罰。 每當你檢定失敗，這包括你豁免檢定失敗，攻擊檢定未命中，其他檢定沒到達DC等情況。除非是為了重新嘗試這個技能檢定，否則，你在其他全檢定中承受1DP減值，可以疊加，持續一個場景。
A8: 5 | B8: 畸形（-1） | C8: - | D8: 描述：無論是由於邪惡的魔法、疾病或神明的懲罰，你身上有一處先天的畸形，嚴重影響你的身體活動。 你的敏捷相關檢定承受2DP減值。
A9: 6 | B9: 兩性具有（-2） | C9: - | D9: 描述：你是同時擁有男女兩性器官的雙性人。 你在性別的判定上你不屬於男性也不屬於女性，你不能強化前提限定男性或女性的強化，不能使用限定男性或女性使用的物品，除非其有特殊說明。 任何改變性別的相關能力和物品也無法影響你，但是針對性別的效果卻可以如常觸發。
A10: 7 | B10: 玻璃人（-5） | C10: - | D10: 描述：你的身體因為嚴重疾病變得如同玻璃一般脆弱，稍微的碰撞都會使你骨折。 每當你受到傷害時，你的隨機一條肢體都會獲得相當於所受傷害的不可疊加的肢體妨害點數，強韌豁免。並且你清除肢體妨害點數的難度是原本的兩倍，這意味著你清除肢體妨害點數時，假設原本需要1點成功數可以降低1點，則現在需要2點成功數。 說明：需要注意的是，這隻影響清除時的難度，不影響獲得時的豁免檢定。
A11: 8 | B11: 神經協調障礙（-1） | C11: - | D11: 1級：笨手笨腳 描述：你是會走路的人型災難。 你的生理系的相關技能檢定承受1DP點減值。
A12: 9 | B12: 神經協調障礙（-2） | C12: - | D12: 2級：寸草不生 描述：你所到之處雞犬不寧寸草不生，這都要歸功於你那毀滅性的笨手笨腳。 你的生理系屬性的相關檢定承受1DP減值，與1級的效果疊加。
A13: 10 | B13: 舊傷（-1） | C13: - | D13: 描述：你曾經受過致命的重傷，至今仍在受其影響。 你的生命上限永久降低2點。
A14: 11 | B14: 免疫缺陷（-1） | C14: 選擇這個缺陷後，你無法擁有“忍耐力”和“死硬”專長。 | D14: 描述：你的免疫系統非常脆弱，感冒都有可能要了你的命。 你的強韌檢定承受4DP減值。
A15: 12 | B15: 視力缺陷（-1） | C15: - | D15: 描述：你的眼睛有點問題，可能是近視、遠視、散光、老花、青光眼、白內障啥的。 你獲得無法避免的5點目眩點數，無法以下述方式以外的方式移除。 特殊：輪回之境可以修復本缺陷，這需要花費你200分。
... A28: 26 | B28: 傲人身材（-0） | C28: - | D28: 描述：你的胸圍固定為D罩杯或更大。 你失去1點基礎防禦，並且你的反射檢定承受1DP減值。 特殊：只有當你的外觀視覺效果上處於人型時才會受到此缺陷的影響。當你以任何能力消除此缺陷的影響時（包括但不限於隆胸手術、變形術、著裝全封閉盔甲等），你可以無視本缺憾，但是同時失去同名天賦的一切加成。
B29: 精神類缺陷： | D29: -
A30: 27 | B30: 不得安寧（-2） | C30: - | D30: 描述：當你年輕時，一位經常與你發生爭吵的親人去世了，他或她的靈魂未能獲得安息。現在，它那不安的靈魂總是時不時的出現在你身邊對你表示遺憾，使你經常分心。 你無法使用需要維持（專注）的能力，並且你那個去世的親人經常以靈體的形式打攪你（沒有資料）。
A31: 28 | B31: 暴飲暴食（-2） | C31: - | D31: 描述：此缺陷使你極其貪飲貪吃。如果可能，你會吃下大大超過身體需要的食物。你從不願意錯過任何一頓飯。 你每天必須吃完三人份的食物，並且每當你進行短休或者長休後的一個小時之內，由於暴飲暴食，你的全檢定承受1DP減值。 同時，當面對美食這類誘惑時，若你需要對抗不進食的話，你的對抗檢定失去一半成功數。
A32: 29 | B32: 社恐（-2） | C32: - | D32: 描述：你是個陰角，你害怕在公眾場合進行交流，害怕公然成為他人矚目的對象。 當處於你視覺線內的目標超過一個時，你對處於你視覺線內的目標進行的的風度和操控相關檢定分別受到4DP減值。
A33: 30 | B33: 恐蟲（-1） | C33: - | D33: 描述：你年幼時跟蟲類之間發生過的慘痛經歷使你深深地對各種蟲感到恐懼，特別是當它們彙聚成群時。 你在與蟲類外型的生物或者蟲類作戰時（包括並肩作戰），你的攻擊檢定承受3DP減值，基礎防禦減少3點。
A34: 31 | B34: 恐火（-3） | C34: - | D34: 描述：你曾經因火災或其他一些類似事件而受到嚴重燒傷，疤痕至今未退。你一旦靠近火源便會陷入恐懼之中。 你在對抗能夠豁免的火焰傷害或燃燒點數時，你的豁免檢定承受6DP減值。你的2米記憶體在明火時，你的全檢定承受1DP減值。
A35: 32 | B35: 恐火（-4） | C35: - | D35: 你的身體受到了毀滅性的燒傷，你能夠活下來已經是奇跡，哪怕一點火焰對你來說都充滿致命的危險。 當你受到火焰傷害或燃燒點數時，最終傷害額外受到3點火焰嚴重傷害或者燃燒點數。
A36: 33 | B36: 電波系（-1） | C36: - | D36: 描述：你就是會走路的毒電波發射塔，沒人能跟上你的思路。 你所有互動系技能的相關檢定承受1DP減值。
A37: 34 | B37: 空氣朋友（-2） | C37: - | D37: 描述：你有一個空氣朋友，你經常對著他說話，每個星期還要付給他50塊錢。 你太悲慘了，所有人由於蔑視你，在對你進行互動系相關檢定時都可以獲得2DP完美加值。
A38: 35 | B38: 丟三落四（-1） | C38: - | D38: 描述：你粗心大意，容易遺失重要的東西。 每當你離開一個逗留了一小時以上的地點，你必須投擲一個1D10，這不是一次檢定。若結果不為10，則你會隨機遺失一個物品（一整個錢包視為一個物體）。武器、盔甲等穿戴的物品不會遺失，載具也不會，但是載具變為的膠囊會遺失。
A39: 36 | B39: 獨來獨往（-2） | C39: - | D39: 描述：你出身於海盜、土匪或其他類似習慣於插兄弟肋骨兩刀的環境，你已經習慣什麼事情都只依靠自己。盟友的存在會很容易讓你分心，你需要擁有隻屬於你自己的空間才能將事情做到最好。 效果：你和盟友一同行動時，你的全檢定承受2DP減值。 特殊：由於本缺憾會影響玩家集體行動導致分團而影響劇情，甚至會影響PC團結，所以ST有權禁用本缺憾。
A40: 37 | B40: 反應遲鈍（-1） | C40: - | D40: 描述：你對於察覺危險總是慢一拍。 你的先攻檢定承受3點減值。
A41: 38 | B41: 感情用事（-1） | C41: - | D41: 描述：你過於感性，總是在不恰當的時機走神。 若你跟原本與你態度友善或以上的目標作戰，你在戰鬥中的全檢定承受2DP減值。
... A79: 76 | B79: 怕黑（-1） | C79: - | D79: 描述：你在黑暗中有過無法遺忘的恐怖遭遇，至今你一進入黑暗環境就會覺得快要死到臨頭。 當你處於光照條件為昏暗或黑暗的環境時，你的三豁免檢定承受3DP減值。
B80: 特異類缺陷：
A81: 77 | B81: 幸運E（-1） | C81: - | D81: 描述：你很倒楣，事情總在最糟糕的時候變得更糟。 你進行機運骰時，若為成功則為失敗，若為失敗則為大失敗。
A82: 78 | B82: 短命（-1） | C82: - | D82: 描述：你的壽命比常人更短。 你在獲得此缺陷時投2D3，你的自然壽命減少骰出的數值*10年。 特殊：此缺陷可以重複選擇，並且選擇本缺陷後，你無法通過任何方式變得壽命無限。
A83: 79 | B83: 受動物厭惡者（-1） | C83: - | D83: 描述：你天生就受到動物們的討厭。 所有動物對你的初始態度下降一級，並且對你態度為不為敵對的自然本質的動物們不會自願近接你的10米之內，除非你或那動物的主人成功通過DC 10的馴養動物、騎乘戰鬥或改善動物態度。
A84: 80 | B84: 汙穢烙印（-1） | C84: - | D84: 描述：你的血肉上天生烙有一個邪惡的印記，其可能來自超越心智的恐怖。 你需要選擇印記所處的部位。 若此印記在你的手，你的敏捷相關檢定承受2DP減值。 若此印記在你的臉，你的風度相關檢定承受2DP減值。 若此印記在你的軀幹，你的力量相關檢定承受2DP減值。
A85: 81 | B85: 神隱（-2） | C85: - | D85: 描述：當你還是一個孩子時，你曾被神秘的存在拐走了一段時間。當你回來以後，你仍對那段經歷念念不忘。你渴望回到那個地方，並覺得凡人的世界如此沉悶而令人作嘔，所以你平時毫無食慾，並且對各種奇怪景象視若無睹。 效果：你對抗疾病、幻覺和所有類型的毒藥的豁免承受3DP減值。你對抗妖怪施放的法術、能力和技能進行的豁免承受3DP減值。
A86: 82 | B86: 路痴（-1） | C86: - | D86: 描述：你完全沒有方向感，在直路上都能迷路。 你的追蹤檢定自動失敗，當你和你的隊友分頭行動時，你無法通過移動的方式主動和隊友匯合。
A87: 83 | B87: 音痴（-2） | C87: - | D87: 描述：你對音樂本身完全沒有一點感覺。 你進行的歌唱相關檢定和演奏相關檢定自動失敗，你無法受到任何基於歌唱和演奏相關能力的正面影響。
A88: 84 | B88: 女難之相（-3） | C88: - | D88: 描述：又稱桃花劫，你總是被各種意義上不得了的女人纏上。 任何女性生物對你進行的互動檢定獲得2點附加成功，任何女性生物對你進行的尾隨（追蹤檢定）自動成功。
A89: 85 | B89: 無魔體質（-4） | C89: - | D89: 描述：你天生就和魔法神秘之類的東西無緣，即使你來到了異世界也一樣。 效果：你無法施法，你進行神秘學相關技能的檢定時自動失敗，你無法用神秘學代替任何技能進行檢定。
...

Sheet 天賦 3xx
A1: 編號 | B1: 天賦 | C1: 前提 | D1: 效果
A2: 0 | B2: - | C2: - | D2: -
B3: 生理類天賦： | D3: -
A4: 1 | B4: 絕對時間感知（1） | C4: - | D4: 描述：你腦子裡的好像有一塊精準的表。 你總是知道現在是什麼時候，精度以秒計算。你可以以同樣的精度測算經過的時間長度。時區變化或者打瞌睡都不會影響此能力，你可以在你事先選定的時間點醒過來。時空的變換不會影響你。你總是在絕對的意義上知道當前的時間，當你在時空中旅行，ST會告訴你“你向過去行進了92876.3天”，並令你——或其它人——自行解決類似“那TM閏年怎麼計算啊？”的問題。
A5: 2 | B5: 舉重(1) | C5: - | D5: 描述：你可以舉起比你體重更重的東西。 當在你進行負重計算時，你的負重能力翻倍。
A6: 3 | B6: 快速康復（1） | C6: 你不能擁有“自愈障礙”缺陷 | D6: 描述：你身體的恢復速度很快。 你的自然恢復速度翻倍（短休若原本是1小時，現在變為半小時，最低15分鐘，長休若原本是8小時，現在變為4小時，最低2小時）。
A7: 4 | B7: 敏銳感覺系列（3） | C7: 你不能擁有對應感官的缺陷，如，你不能既擁有“視力缺陷”缺陷又擁有“敏銳視覺”天賦。 | D7: 描述：你擁有超人般的感覺。 每個敏銳感覺特性都是獨立的天賦，分為視聽觸嗅味五個感官，購買後選擇一個獲得，每個選項只能選擇一次： 聽覺：你獲得靈敏聽覺。 嗅覺：你獲得靈敏嗅覺。 味覺：當你服用任何非正常食物、水時，你可以立即發現不對勁（如下毒，過期等），前提是你吃過正常的食物。只要你不願意，你不會受到任何口服藥水，毒藥，毒品等類似物品的不良影響。 視覺：你忽略8點高速優勢。 觸及：你免疫B級接觸攻擊。
A8: 5 | B8: 柔韌身體（1） | C8: - | D8: 描述：你的身體柔韌性非比尋常。 當你通過狹小空間時，你無需額外花費移動力，也不會失去基礎防禦。
A9: 6 | B9: 完美形體（3） | C9: - | D9: 描述：你天生擁有對於你的種族來說完美的肉體。 你額外獲得1點可分配的建卡屬性點，但依然不能使任何屬性超過5。
A10: 7 | B10: 閃電先攻（3） | C10: - | D10: 描述：你擁有驚人的行動力。 你的先攻提升6點。
A11: 8 | B11: 完美平衡（2） | C11: - | D11: 描述：通常的狀況下，無論行走在多麼窄多麼滑的表面上，你不會摔倒。 1級：你在進行平衡感的相關檢定時獲得4DP專長加值，並且你免疫困難地形。
A12: 9 | B12: 危險感知（9） | C12: - | D12: 描述：你擁有一種在危險迫近時能夠提醒他的敏銳的生存本能。也許他可以熟練的察覺周圍環境中的細微線索，或者擁有神秘的第六感幫他消除將要到來的麻煩和危險。當即將遇到危險時，你會有一種奇妙的反應，可能是以頭髮豎起、手臂的雞皮疙瘩、背脊升起的寒氣。 你免疫突襲。
A13: 10 | B13: 夜視（1） | C13: 你不能擁有“視力缺陷”。 | D13: 描述：你的眼睛如同貓一樣可以晚上視物。 你獲得黑暗視覺。
A14: 11 | B14: 遠視（1） | C14: 你不能擁有“視力缺陷”。 | D14: 描述：你可以將你的眼睛聚焦，如同使用瞭望遠鏡。 你可以在模糊範圍內進行特定部位攻擊。
A15: 12 | B15: 自然免疫（2） | C15: 你不能擁有“免疫障礙”缺陷。 | D15: 描述：你重病的次數屈指可數。 你免疫自然本質的毒素和疾病效果。
... A18: 15 | B18: 傲人身材(0) | C18: 只有選擇了同名缺陷才能擁有此天賦。 | D18: 描述：你善於利用自己身體的優勢。 當你在與性取向為女性的角色社交時，你的唬騙和交際相關檢定獲得1DP專長加值。 在非戰鬥情況下，你可以將一支筆、一部手機或類似的小型物件夾在胸口。這種情況下，你的隱藏（隱藏物品）檢定獲得1DP專長加值。 特殊：只有當你的外觀視覺效果上處於人型時才會受到此天賦的影響。當你以任何能力消除同名缺陷的影響時（包括但不限於縮胸手術、變形術、著裝全封閉盔甲等），你同時失去此天賦的一切加成。
B19: 精神類天賦： | D19: -
A20: 16 | B20: 常識（3） | C20: - | D20: 描述：你具有傑出的基礎知識，並且注重實效。通常你可以依據所掌握的那些東西在一小段時間的思考之後，做出直接且可靠的決定。 每場景一次，當你覺得接下來做出的一個行動可能會引起災難性後果時，或者當你覺得你在一個情節的關鍵處被徹底難倒沒了主意的時候，你可以告訴ST你現在即將要做的事情，然後ST會指出你的行為導致的直接結果，這會讓你有機會改變自己的做法，從而避免某些風險。 需要注意的是，你每場冒險世界使用本能力的次數不得超過你傳奇智力或者傳奇感知取高+1/次。 ST可以以任何理由禁用此天賦。
A21: 17 | B21: 感受（2） | C21: - | D21: 描述：你非常容易感受他人的情緒。 你的感受技能的相關檢定獲得3DP專長加值。
A22: 18 | B22: 直覺(3) | C22: - | D22: 描述：你通常都能猜對。 當你面對選擇時，你可以要求ST讓你使用直覺。 花費1點意志力，你進行一次感知檢定，DC=5，成功後你告知ST你要達成的目標，然後ST會從你給出個選項裡面告訴你“最快”或“最穩”或“分數最多”（由你選擇）的途徑。每使用一次，在接下來影片中你再次使用直覺時，DC+5。 注意：你只能選擇既定的結果，如獲得某個物品，殺死某個目標等，而不能選擇概念性目標，比如我要刷最多分等。並且選項為你給ST，並非ST告訴你選項。若你的選項糟糕透頂，ST也會從裡面按照你要求的選擇最好的給你，當然也可能依然糟糕透頂。若所有選項皆無法達成目標，則ST可以告訴你，你的直覺告訴你，你所有的主意都糟糕透頂，你覺得無法達成目標。 ST可以以任何理由禁用此天賦。
A23: 19 | B23: 靈感(1) | C23: “直覺”天賦 | D23: 描述：你的天賦如此出色純熟。 效果：現在你在進行直覺檢定時，獲得5個附加成功，而且你第一次使用直覺時，無需擲骰。
A24: 20 | B24: 社牛（3） | C24: 不能擁有“社恐”缺陷 | D24: 描述：你就是所謂的陽角，擁有強大的社交能力。 你的互動系檢定獲得1DP完美加值。
A25: 21 | B25: 病嬌（1） | C25: - | D25: 描述：你對你喜歡的存在愛到痴狂，想要將其永遠獨佔。 你設置1至3個外貌或心理上的特點（如“白髮”“溫柔”）。 你對符合其中至少一項的目標進行的追蹤無需判定自動成功。
A26: 22 | B26: 地雷系（2） | C26: 擁有同名怪癖 | D26: 描述：任何觸發你雷點的傢伙都會讓你失去理智。 任何目標一但觸發你的雷點，則你對其進行的攻擊檢定獲得2點附加成功。 持續至你完全無法定位目標，並且進行一次長休後為止。
A27: 23 | B27: 復仇鬼（2） | C27: 擁有“無助”缺陷 | D27: 描述：你是隻為復仇而活的復仇鬼。 “無助”的效果改為，當你視覺線內的友方因攻擊而昏迷或死亡時，你對導致其昏迷或死亡的目標的攻擊檢定獲得3DP表現加值，傷害上限提升3點，持續至目標死亡為止。
A28: 24 | B28: 絕對音感（2） | C28: 不能擁有“音痴”缺陷 | D28: 描述：你天生就擁有對於音樂和音符的絕對感受力。 你的歌唱相關檢定和演奏相關檢定獲得1點附加成功。
B29: 特異類天賦： | D29: -
A30: 25 | B30: 絕處逢生（9） | C30: - | D30: 描述：當你處於瀕死的危險時,幸運女神似乎總是會向你微笑！ 在你經歷的生死關頭（尺度由ST掌握，一般為受到即死效果、本次檢定失敗就會死亡、受到一次攻擊後死亡等）中，本次檢定若為你的檢定或包含你的檢定（包括主動檢定，比如跳過懸崖，或者豁免檢定等）則你可以重投這次檢定中的所有1。若本次檢定為敵人的檢定（比如施法攻擊檢定，攻擊檢定）則其不得獲得任何加骰。本能力每場冒險世界只能使用一次。
A31: 26 | B31: 劇情需要（3） | C31: - | D31: 描述：你具有一種在合適的時間出現在合適的地方的能力。 每場景一次，你能遭遇一次幸運的、但是說得通的可能性。 細節由ST決定。例如ST可能宣佈，PC需要交涉的警衛之一恰好是你的表兄弟；或者，當PC追擊逃跑的銀行搶匪時，銀行外面正好有一輛超級跑車。ST可以裁定，此優勢的一次發動，可以代表某次跑團期間多個乃至全部的“奇跡”（例如，小鎮修車鋪裡正好有所有你修理超科技反引力腰帶所需要的零件）。 你有權向ST建議何時及如何發動這個優勢，但是決定權在他。 你每場冒險世界使用本能力的次數不得超過你傳奇操控+1/次。
A32: 27 | B32: 幸運（1） | C32: - | D32: 描述：你生來就好像被什麼存在眷顧了一般，擁有非同一般的幸運。 當你進行一次檢定時，在檢定前，你可以選擇發動本天賦，進行2次檢定取兩者中的最好結果。 你每場冒險世界使用本能力的次數不得超過你傳奇操控+1/次。
A33: 28 | B33: 幸運星（1） | C33: “幸運”天賦 | D33: 若一個目標處於你的操控值/米內，則你可以對該目標使用“幸運”的效果。
A34: 29 | B34: 長命（1） | C34: - | D34: 描述：你的壽命比常人更長。 你在獲得此缺陷時投2D2，你的自然壽命增加骰出的數值*10年。 特殊：此天賦可以重複選擇。
A35: 30 | B35: 不老（1） | C35: - | D35: 描述：你擁有不老的容顏。 你選擇10歲～25歲之間的一個年齡，你的肉體和外貌年齡永遠保持在你選擇的年齡。你不會因為年齡的增加和衰老效果而受到任何減值。
A36: 31 | B36: 桃花運（4） | C36: - | D36: 描述：你總是能夠吸引來各種各樣的女性的愛慕。 你對女性生物的互動系檢定獲得1點附加成功。
A37: 32 | B37: 耐摔王（1） | C37: - | D37: 當你即將承受墜落傷害時，若高度低於你的（敏捷值+力量值）*2米，你可以無需動作喊出“what can I say？”，若如此做，你可以免疫本次墜落傷害。
A38: 33 | B38: 法術絕緣體（3） | C38: 前提：擁有“無魔體質”缺陷 | D38: 描述：你與法術和神秘完全無緣，因此任何法術都難以傷害你。 你獲得【法術抗力4】。
A39: 34 | B39: 倖存者（6） | C39: - | D39: 描述：你能夠從各種各樣的交通事故和自然災害中獨自存活下來。 每冒險世界1次，若你遇到交通事故，你必然能從事故中倖存，這意味著針對一次載具的碾壓，撞擊，爆炸事故，你的對抗性檢定必定成功。 每冒險世界1次，若你遇到自然災害，你必然能逃脫到安全地帶。
